Workbook
Name Selected_Standard_Definitions: '2. Dimension Definition'!$4:$4
Name Additional_Custom_Dimensions: '2. Dimension Definition'!$51:$51

Sheet 0. Instructions
B1: Instructions
B2: How to use this template
B5: # | C5: Instruction
B6: 1 | C6: Navigate to the Task Type & Dimension Selection tab
B7: 2 | C7: In the Task Type & Dimension Selection tab, select all of the Task Types (e.g., SFT, RLHF, Rubrics) that are contained in your project as well as the Verticals associated (Languages, Experts, Code). The Standard Dimensions and Sub-Dimensions corresponding to those Task Types (e.g., Prompt - Feasibility) will populate automatically. Note: en_US or "Generalists" tasks are included in the Languages selection
B8: 3 | C8: For each Standard Dimension+Sub-Dimension in the Task Type & Dimension Selection tab, use the corresponding checkbox to indicate whether it is applicable to your project Note: Do not edit the "Late Addition" column unless you have already proceeded to step Tab:3 and made edits. Checking this column for late additions is vital to ensure your revisions on tab 3 do not become misaligned
B9: 4 | C9: Navigate to the Dimension Definition tab. The Selected Standard Dimensions section (row 4) is automatically populated with all of the Standard Dimension & Sub-Dimensions that you marked as applicable in the previous step, along with each Standard definitions of 1, 3. and 5 quality. Please add any error categories that you would like used as [Error Category] within any new dimensions you add
B10: 5 | C10: For each Standard Dimension & Sub-Dimension in the Dimension Definition tab, you have the opportunity to request a revision to the 1, 3, and/or 5 quality definitions.
B11: 6 | C11: Navigate within the Dimension Definition tab to the Additional Custom Dimensions section. Here you have the opportunity to add custom dimensions that are unique to your project / not already captuired in the standard dimensions.
B12: 7 | C12: Message [QC member TBD] to signal that you've finished completing the template
B13: 8 | C13: If QC or MLDG has feedback for the standards return to the 2.Dimension Definition tab to update the revised language to match shared understanding
B14: 9 | C14: In the PT & QC Sample Audit Alignment tab, complete at least five sample audits using the Output Rubric
B15: 10 | C15: Got a minute? Share your thoughts in our New Spec Process Survey and help us improve!
B18: # | C18: Additional Links & Videos
B19: 1 | C19: Spec Doc Template
B20: 2 | C20: Project Team How To - First 2 minutes are general basics - Next 6 minutes are walkthrough with example project
B21: 3 | C21: QC <> MLDG How To

Sheet 1. Task Type & Dimension Select
B1: Task Type & Dimension Selection
B2: Project Team Input
B4: Vertical | C4: Languages, Code | H4: =IFERROR(__xludf.DUMMYFUNCTION("unique(filter('A. Standard Dimensions & Rating'!B2:B1003,'A. Standard Dimensions & Rating'!B2:B1003<>""All""))"),"Agents") -> Agents | I4: =IFERROR(__xludf.DUMMYFUNCTION("unique(filter('A. Standard Dimensions & Rating'!A2:A1003,'A. Standard Dimensions & Rating'!A2:A1003<>""All""))"),"Code") -> Code
H5: =IFERROR(__xludf.DUMMYFUNCTION("""COMPUTED_VALUE"""),"Audio") -> Audio | I5: =IFERROR(__xludf.DUMMYFUNCTION("""COMPUTED_VALUE"""),"Experts") -> Experts
B6: Task Type(s) | C6: SFT | H6: =IFERROR(__xludf.DUMMYFUNCTION("""COMPUTED_VALUE"""),"Data_Science") -> Data_Science | I6: =IFERROR(__xludf.DUMMYFUNCTION("""COMPUTED_VALUE"""),"Languages") -> Languages
F7: Only select one | H7: =IFERROR(__xludf.DUMMYFUNCTION("""COMPUTED_VALUE"""),"MM_Image") -> MM_Image
B8: Task Type | C8: Dimension | D8: Sub-Dimension | E8: "5 out of 5" Definition | F8: Applicable? | G8: Late Addition? | H8: =IFERROR(__xludf.DUMMYFUNCTION("""COMPUTED_VALUE"""),"RLHF/Evals") -> RLHF/Evals
B9: =IFERROR(__xludf.DUMMYFUNCTION("iferror(FILTER( { 'A. Standard Dimensions & Rating'!B2:D1003, 'A. Standard Dimensions & Rating'!G2:G1003 }, ( ('A. Standard Dimensions & Rating'!A2:A1003=""All"") + ISNUMBER(MATCH('A. Standard Dimensions & Rating'!A2:A1003, IF(C4<>"""", SPLIT(C4, "", ""),"&" {""""}), 0)) ) * ( ('A. Standard Dimensions & Rating'!B2:B1003=""All"") + ISNUMBER(MATCH('A. Standard Dimensions & Rating'!B2:B1003, IF(C6<>"""", SPLIT(C6, "", ""), {""""}), 0)) ) ), """")"),"All") -> All | C9: =IFERROR(__xludf.DUMMYFUNCTION("""COMPUTED_VALUE"""),"Prompt") -> Prompt | D9: =IFERROR(__xludf.DUMMYFUNCTION("""COMPUTED_VALUE"""),"Unique Ground Truth") -> Unique Ground Truth | E9: =IFERROR(__xludf.DUMMYFUNCTION("""COMPUTED_VALUE"""),"- The prompt has a unique ground truth answer. All the experts on the subject would come to the same conclusion") -> - The prompt has a unique ground truth answer. All the experts on the subject would come to the same conclusion | F9: TRUE | G9: FALSE | H9: =IFERROR(__xludf.DUMMYFUNCTION("""COMPUTED_VALUE"""),"Rubrics") -> Rubrics
B10: =IFERROR(__xludf.DUMMYFUNCTION("""COMPUTED_VALUE"""),"All") -> All | C10: =IFERROR(__xludf.DUMMYFUNCTION("""COMPUTED_VALUE"""),"Prompt") -> Prompt | D10: =IFERROR(__xludf.DUMMYFUNCTION("""COMPUTED_VALUE"""),"Timelessness") -> Timelessness | E10: =IFERROR(__xludf.DUMMYFUNCTION("""COMPUTED_VALUE"""),"- The answer to the prompt is not time dependent") -> - The answer to the prompt is not time dependent | F10: FALSE | G10: FALSE | H10: =IFERROR(__xludf.DUMMYFUNCTION("""COMPUTED_VALUE"""),"SFT") -> SFT
B11: =IFERROR(__xludf.DUMMYFUNCTION("""COMPUTED_VALUE"""),"All") -> All | C11: =IFERROR(__xludf.DUMMYFUNCTION("""COMPUTED_VALUE"""),"Prompt") -> Prompt | D11: =IFERROR(__xludf.DUMMYFUNCTION("""COMPUTED_VALUE"""),"Prompt Clarity and Specificity / Unique Ground Truth") -> Prompt Clarity and Specificity / Unique Ground Truth | E11: =IFERROR(__xludf.DUMMYFUNCTION("""COMPUTED_VALUE"""),"- The prompt has a unique ground truth answer. Any variances in the GTFA are still equivalent (e.g., π vs. 3.14, IUPAC name vs. common name). All the experts on the subject would come to the same conclusion") -> - The prompt has a unique ground truth answer. Any variances in the GTFA are still equivalent (e.g., π vs. 3.14, IUPAC name vs. common name). All the experts on the subject would come to the same conclusion | F11: FALSE | G11: FALSE | H11: =IFERROR(__xludf.DUMMYFUNCTION("""COMPUTED_VALUE"""),"Tool_Use") -> Tool_Use
B12: =IFERROR(__xludf.DUMMYFUNCTION("""COMPUTED_VALUE"""),"All") -> All | C12: =IFERROR(__xludf.DUMMYFUNCTION("""COMPUTED_VALUE"""),"Prompt") -> Prompt | D12: =IFERROR(__xludf.DUMMYFUNCTION("""COMPUTED_VALUE"""),"Domain Relevance") -> Domain Relevance | E12: =IFERROR(__xludf.DUMMYFUNCTION("""COMPUTED_VALUE"""),"- The Prompt(s) are clearly related to the assigned domain.") -> - The Prompt(s) are clearly related to the assigned domain. | F12: FALSE | G12: FALSE | H12: =IFERROR(__xludf.DUMMYFUNCTION("""COMPUTED_VALUE"""),"Translation") -> Translation
B13: =IFERROR(__xludf.DUMMYFUNCTION("""COMPUTED_VALUE"""),"All") -> All | C13: =IFERROR(__xludf.DUMMYFUNCTION("""COMPUTED_VALUE"""),"Prompt") -> Prompt | D13: =IFERROR(__xludf.DUMMYFUNCTION("""COMPUTED_VALUE"""),"Category Relevance") -> Category Relevance | E13: =IFERROR(__xludf.DUMMYFUNCTION("""COMPUTED_VALUE"""),"- The Prompt clearly fits the assigned category and showcases subject expertise") -> - The Prompt clearly fits the assigned category and showcases subject expertise | F13: FALSE | G13: FALSE | H13: =IFERROR(__xludf.DUMMYFUNCTION("""COMPUTED_VALUE"""),"UI") -> UI
B14: =IFERROR(__xludf.DUMMYFUNCTION("""COMPUTED_VALUE"""),"All") -> All | C14: =IFERROR(__xludf.DUMMYFUNCTION("""COMPUTED_VALUE"""),"Prompt") -> Prompt | D14: =IFERROR(__xludf.DUMMYFUNCTION("""COMPUTED_VALUE"""),"Reasoning Requirement") -> Reasoning Requirement | E14: =IFERROR(__xludf.DUMMYFUNCTION("""COMPUTED_VALUE"""),"- The prompt requires reasoning in-line with the assigned domain/expertise level, beyond jsut simple recall") -> - The prompt requires reasoning in-line with the assigned domain/expertise level, beyond jsut simple recall | F14: FALSE | G14: FALSE
B15: =IFERROR(__xludf.DUMMYFUNCTION("""COMPUTED_VALUE"""),"All") -> All | C15: =IFERROR(__xludf.DUMMYFUNCTION("""COMPUTED_VALUE"""),"Prompt") -> Prompt | D15: =IFERROR(__xludf.DUMMYFUNCTION("""COMPUTED_VALUE"""),"Difficulty") -> Difficulty | E15: =IFERROR(__xludf.DUMMYFUNCTION("""COMPUTED_VALUE"""),"- The prompt perfectly matches the assigned difficulty level") -> - The prompt perfectly matches the assigned difficulty level | F15: FALSE | G15: FALSE
B16: =IFERROR(__xludf.DUMMYFUNCTION("""COMPUTED_VALUE"""),"All") -> All | C16: =IFERROR(__xludf.DUMMYFUNCTION("""COMPUTED_VALUE"""),"Prompt") -> Prompt | D16: =IFERROR(__xludf.DUMMYFUNCTION("""COMPUTED_VALUE"""),"Constraints") -> Constraints | E16: =IFERROR(__xludf.DUMMYFUNCTION("""COMPUTED_VALUE"""),"- Any constraints feel natural and are what a real user asking this question to a chatbot would want ") -> - Any constraints feel natural and are what a real user asking this question to a chatbot would want | F16: FALSE | G16: FALSE
B17: =IFERROR(__xludf.DUMMYFUNCTION("""COMPUTED_VALUE"""),"All") -> All | C17: =IFERROR(__xludf.DUMMYFUNCTION("""COMPUTED_VALUE"""),"Prompt") -> Prompt | D17: =IFERROR(__xludf.DUMMYFUNCTION("""COMPUTED_VALUE"""),"Prompt Validity") -> Prompt Validity | E17: =IFERROR(__xludf.DUMMYFUNCTION("""COMPUTED_VALUE"""),"- The task is marked correctly as invalid or valid.") -> - The task is marked correctly as invalid or valid. | F17: FALSE | G17: FALSE
B18: =IFERROR(__xludf.DUMMYFUNCTION("""COMPUTED_VALUE"""),"All") -> All | C18: =IFERROR(__xludf.DUMMYFUNCTION("""COMPUTED_VALUE"""),"All CB Generated Content") -> All CB Generated Content | D18: =IFERROR(__xludf.DUMMYFUNCTION("""COMPUTED_VALUE"""),"Unlisted Minor Errors") -> Unlisted Minor Errors | E18: =IFERROR(__xludf.DUMMYFUNCTION("""COMPUTED_VALUE"""),"- There are no unlisted errors that you feel degrade the quality of the task") -> - There are no unlisted errors that you feel degrade the quality of the task | F18: FALSE | G18: FALSE
B19: =IFERROR(__xludf.DUMMYFUNCTION("""COMPUTED_VALUE"""),"All") -> All | C19: =IFERROR(__xludf.DUMMYFUNCTION("""COMPUTED_VALUE"""),"All CB Generated Content") -> All CB Generated Content | D19: =IFERROR(__xludf.DUMMYFUNCTION("""COMPUTED_VALUE"""),"Un-auditable") -> Un-auditable | F19: FALSE | G19: FALSE
B20: =IFERROR(__xludf.DUMMYFUNCTION("""COMPUTED_VALUE"""),"SFT") -> SFT | C20: =IFERROR(__xludf.DUMMYFUNCTION("""COMPUTED_VALUE"""),"Prompt") -> Prompt | D20: =IFERROR(__xludf.DUMMYFUNCTION("""COMPUTED_VALUE"""),"Prompt Clarity and Specificity") -> Prompt Clarity and Specificity | E20: =IFERROR(__xludf.DUMMYFUNCTION("""COMPUTED_VALUE"""),"- There is little to no room for misinterpretation of the specific request - Prompt has a specific request that doesn't require more than one minor assumption to answer it") -> - There is little to no room for misinterpretation of the specific request - Prompt has a specific request that doesn't require more than one minor assumption to answer it | F20: TRUE | G20: FALSE
B21: =IFERROR(__xludf.DUMMYFUNCTION("""COMPUTED_VALUE"""),"SFT") -> SFT | C21: =IFERROR(__xludf.DUMMYFUNCTION("""COMPUTED_VALUE"""),"Prompt") -> Prompt | D21: =IFERROR(__xludf.DUMMYFUNCTION("""COMPUTED_VALUE"""),"Feasibility") -> Feasibility | E21: =IFERROR(__xludf.DUMMYFUNCTION("""COMPUTED_VALUE"""),"- The prompt is completely actionable by an LLM or chatbot - The prompt contains no conflicting instructions/statements ") -> - The prompt is completely actionable by an LLM or chatbot - The prompt contains no conflicting instructions/statements | F21: FALSE | G21: FALSE
B22: =IFERROR(__xludf.DUMMYFUNCTION("""COMPUTED_VALUE"""),"SFT") -> SFT | C22: =IFERROR(__xludf.DUMMYFUNCTION("""COMPUTED_VALUE"""),"Prompt") -> Prompt | D22: =IFERROR(__xludf.DUMMYFUNCTION("""COMPUTED_VALUE"""),"Multiturn: Conversational Flow") -> Multiturn: Conversational Flow | E22: =IFERROR(__xludf.DUMMYFUNCTION("""COMPUTED_VALUE"""),"- All follow-up prompts are grounded in the conversation and do not digress the conversation from the first turn of the prompt") -> - All follow-up prompts are grounded in the conversation and do not digress the conversation from the first turn of the prompt | F22: FALSE | G22: FALSE
B23: =IFERROR(__xludf.DUMMYFUNCTION("""COMPUTED_VALUE"""),"SFT") -> SFT | C23: =IFERROR(__xludf.DUMMYFUNCTION("""COMPUTED_VALUE"""),"Prompt") -> Prompt | D23: =IFERROR(__xludf.DUMMYFUNCTION("""COMPUTED_VALUE"""),"Prompt Category") -> Prompt Category | E23: =IFERROR(__xludf.DUMMYFUNCTION("""COMPUTED_VALUE"""),"- The prompt content matches the category selected") -> - The prompt content matches the category selected | F23: FALSE | G23: FALSE
B24: =IFERROR(__xludf.DUMMYFUNCTION("""COMPUTED_VALUE"""),"SFT") -> SFT | C24: =IFERROR(__xludf.DUMMYFUNCTION("""COMPUTED_VALUE"""),"Prompt") -> Prompt | D24: =IFERROR(__xludf.DUMMYFUNCTION("""COMPUTED_VALUE"""),"Contrived / Unnatural Prompts") -> Contrived / Unnatural Prompts | E24: =IFERROR(__xludf.DUMMYFUNCTION("""COMPUTED_VALUE"""),"- The prompt is neither contrived or unnatural") -> - The prompt is neither contrived or unnatural | F24: TRUE | G24: FALSE
B25: =IFERROR(__xludf.DUMMYFUNCTION("""COMPUTED_VALUE"""),"SFT") -> SFT | C25: =IFERROR(__xludf.DUMMYFUNCTION("""COMPUTED_VALUE"""),"Prompt") -> Prompt | D25: =IFERROR(__xludf.DUMMYFUNCTION("""COMPUTED_VALUE"""),"Prompt Ratability") -> Prompt Ratability | E25: =IFERROR(__xludf.DUMMYFUNCTION("""COMPUTED_VALUE"""),"- Prompt is correctly marked as rateable or ratable") -> - Prompt is correctly marked as rateable or ratable | F25: FALSE | G25: FALSE
B26: =IFERROR(__xludf.DUMMYFUNCTION("""COMPUTED_VALUE"""),"SFT") -> SFT | C26: =IFERROR(__xludf.DUMMYFUNCTION("""COMPUTED_VALUE"""),"Prompt") -> Prompt | D26: =IFERROR(__xludf.DUMMYFUNCTION("""COMPUTED_VALUE"""),"Prompt Localization") -> Prompt Localization | E26: =IFERROR(__xludf.DUMMYFUNCTION("""COMPUTED_VALUE"""),"- The prompt is appropriate given its intended locale") -> - The prompt is appropriate given its intended locale | F26: FALSE | G26: FALSE
B27: =IFERROR(__xludf.DUMMYFUNCTION("""COMPUTED_VALUE"""),"SFT") -> SFT | C27: =IFERROR(__xludf.DUMMYFUNCTION("""COMPUTED_VALUE"""),"Prompt") -> Prompt | D27: =IFERROR(__xludf.DUMMYFUNCTION("""COMPUTED_VALUE"""),"Code coherence with request") -> Code coherence with request | E27: =IFERROR(__xludf.DUMMYFUNCTION("""COMPUTED_VALUE"""),"- The code in the prompt is completely coherent with the request - The code in the prompt completely aligns with how it's described in the prompt's text") -> - The code in the prompt is completely coherent with the request - The code in the prompt completely aligns with how it's described in the prompt's text | F27: FALSE | G27: FALSE
B28: =IFERROR(__xludf.DUMMYFUNCTION("""COMPUTED_VALUE"""),"SFT") -> SFT | C28: =IFERROR(__xludf.DUMMYFUNCTION("""COMPUTED_VALUE"""),"Prompt") -> Prompt | D28: =IFERROR(__xludf.DUMMYFUNCTION("""COMPUTED_VALUE"""),"Prompt Coding Language") -> Prompt Coding Language | E28: =IFERROR(__xludf.DUMMYFUNCTION("""COMPUTED_VALUE"""),"- Prompts adhere to the specified coding language or allowed coding languages within the project.") -> - Prompts adhere to the specified coding language or allowed coding languages within the project. | F28: FALSE | G28: FALSE
B29: =IFERROR(__xludf.DUMMYFUNCTION("""COMPUTED_VALUE"""),"SFT") -> SFT | C29: =IFERROR(__xludf.DUMMYFUNCTION("""COMPUTED_VALUE"""),"Prompt") -> Prompt | D29: =IFERROR(__xludf.DUMMYFUNCTION("""COMPUTED_VALUE"""),"Truthfulness") -> Truthfulness | E29: =IFERROR(__xludf.DUMMYFUNCTION("""COMPUTED_VALUE"""),"- The prompt has no factual errors - The prompt has no misleading statements") -> - The prompt has no factual errors - The prompt has no misleading statements | F29: TRUE | G29: FALSE
B30: =IFERROR(__xludf.DUMMYFUNCTION("""COMPUTED_VALUE"""),"SFT") -> SFT | C30: =IFERROR(__xludf.DUMMYFUNCTION("""COMPUTED_VALUE"""),"Prompt") -> Prompt | D30: =IFERROR(__xludf.DUMMYFUNCTION("""COMPUTED_VALUE"""),"LaTeX Formatting") -> LaTeX Formatting | E30: =IFERROR(__xludf.DUMMYFUNCTION("""COMPUTED_VALUE"""),"- The prompt uses correct LaTeX formatting where required") -> - The prompt uses correct LaTeX formatting where required | F30: FALSE | G30: FALSE
B31: =IFERROR(__xludf.DUMMYFUNCTION("""COMPUTED_VALUE"""),"SFT") -> SFT | C31: =IFERROR(__xludf.DUMMYFUNCTION("""COMPUTED_VALUE"""),"Response") -> Response | D31: =IFERROR(__xludf.DUMMYFUNCTION("""COMPUTED_VALUE"""),"Accuracy") -> Accuracy | E31: =IFERROR(__xludf.DUMMYFUNCTION("""COMPUTED_VALUE"""),"- The response has no factual errors - The response has no misleading statements") -> - The response has no factual errors - The response has no misleading statements | F31: FALSE | G31: FALSE
B32: =IFERROR(__xludf.DUMMYFUNCTION("""COMPUTED_VALUE"""),"SFT") -> SFT | C32: =IFERROR(__xludf.DUMMYFUNCTION("""COMPUTED_VALUE"""),"Response") -> Response | D32: =IFERROR(__xludf.DUMMYFUNCTION("""COMPUTED_VALUE"""),"Instruction Following / Response Fulfillment") -> Instruction Following / Response Fulfillment | E32: =IFERROR(__xludf.DUMMYFUNCTION("""COMPUTED_VALUE"""),"- All explicit instructions are clearly followed - The response fully answers the question ") -> - All explicit instructions are clearly followed - The response fully answers the question | F32: FALSE | G32: FALSE
B33: =IFERROR(__xludf.DUMMYFUNCTION("""COMPUTED_VALUE"""),"SFT") -> SFT | C33: =IFERROR(__xludf.DUMMYFUNCTION("""COMPUTED_VALUE"""),"Response") -> Response | D33: =IFERROR(__xludf.DUMMYFUNCTION("""COMPUTED_VALUE"""),"Comparison to Original Model Response") -> Comparison to Original Model Response | E33: =IFERROR(__xludf.DUMMYFUNCTION("""COMPUTED_VALUE"""),"- The updated response would clearly perform better overall across quality dimensions") -> - The updated response would clearly perform better overall across quality dimensions | F33: FALSE | G33: FALSE
B34: =IFERROR(__xludf.DUMMYFUNCTION("""COMPUTED_VALUE"""),"SFT") -> SFT | C34: =IFERROR(__xludf.DUMMYFUNCTION("""COMPUTED_VALUE"""),"Response") -> Response | D34: =IFERROR(__xludf.DUMMYFUNCTION("""COMPUTED_VALUE"""),"Compilation") -> Compilation | E34: =IFERROR(__xludf.DUMMYFUNCTION("""COMPUTED_VALUE"""),"- Code runs perfectly without any errors or warnings") -> - Code runs perfectly without any errors or warnings | F34: FALSE | G34: FALSE
B35: =IFERROR(__xludf.DUMMYFUNCTION("""COMPUTED_VALUE"""),"SFT") -> SFT | C35: =IFERROR(__xludf.DUMMYFUNCTION("""COMPUTED_VALUE"""),"Response") -> Response | D35: =IFERROR(__xludf.DUMMYFUNCTION("""COMPUTED_VALUE"""),"Execution Output") -> Execution Output | E35: =IFERROR(__xludf.DUMMYFUNCTION("""COMPUTED_VALUE"""),"- Output perfectly aligns with the requirements of the prompt, including edge cases") -> - Output perfectly aligns with the requirements of the prompt, including edge cases | F35: FALSE | G35: FALSE
B36: =IFERROR(__xludf.DUMMYFUNCTION("""COMPUTED_VALUE"""),"SFT") -> SFT | C36: =IFERROR(__xludf.DUMMYFUNCTION("""COMPUTED_VALUE"""),"Response") -> Response | D36: =IFERROR(__xludf.DUMMYFUNCTION("""COMPUTED_VALUE"""),"Performance") -> Performance | E36: =IFERROR(__xludf.DUMMYFUNCTION("""COMPUTED_VALUE"""),"- The code implementation is well-optimized, utilizing efficient algorithms and data structures wherever possible") -> - The code implementation is well-optimized, utilizing efficient algorithms and data structures wherever possible | F36: FALSE | G36: FALSE
B37: =IFERROR(__xludf.DUMMYFUNCTION("""COMPUTED_VALUE"""),"SFT") -> SFT | C37: =IFERROR(__xludf.DUMMYFUNCTION("""COMPUTED_VALUE"""),"Response") -> Response | D37: =IFERROR(__xludf.DUMMYFUNCTION("""COMPUTED_VALUE"""),"Readability") -> Readability | E37: =IFERROR(__xludf.DUMMYFUNCTION("""COMPUTED_VALUE"""),"- The code is well organized and uses consistent formatting, making it highly readable - Variable/class/method names are meaningfully chosen and are reflective of their purpose") -> - The code is well organized and uses consistent formatting, making it highly readable - Variable/class/method names are meaningfully chosen and are reflective of their purpose | F37: FALSE | G37: FALSE
B38: =IFERROR(__xludf.DUMMYFUNCTION("""COMPUTED_VALUE"""),"SFT") -> SFT | C38: =IFERROR(__xludf.DUMMYFUNCTION("""COMPUTED_VALUE"""),"Response") -> Response | D38: =IFERROR(__xludf.DUMMYFUNCTION("""COMPUTED_VALUE"""),"Code Documentation") -> Code Documentation | E38: =IFERROR(__xludf.DUMMYFUNCTION("""COMPUTED_VALUE"""),"- All code is well documented and includes detailed comments (Documentation constitutes both code comments and docstrings)") -> - All code is well documented and includes detailed comments (Documentation constitutes both code comments and docstrings) | F38: FALSE | G38: FALSE
B39: =IFERROR(__xludf.DUMMYFUNCTION("""COMPUTED_VALUE"""),"SFT") -> SFT | C39: =IFERROR(__xludf.DUMMYFUNCTION("""COMPUTED_VALUE"""),"Response") -> Response | D39: =IFERROR(__xludf.DUMMYFUNCTION("""COMPUTED_VALUE"""),"Code Design") -> Code Design | E39: =IFERROR(__xludf.DUMMYFUNCTION("""COMPUTED_VALUE"""),"- Code implementation follows most of the design principles, making the code easy to maintain and extend down the line (Code design constitutes good programming practices such as modularity, separation of concerns, abstraction, etc)") -> - Code implementation follows most of the design principles, making the code easy to maintain and extend down the line (Code design constitutes good programming practices such as modularity, separation of concerns, abstraction, etc) | F39: FALSE | G39: FALSE
B40: =IFERROR(__xludf.DUMMYFUNCTION("""COMPUTED_VALUE"""),"SFT") -> SFT | C40: =IFERROR(__xludf.DUMMYFUNCTION("""COMPUTED_VALUE"""),"Response") -> Response | D40: =IFERROR(__xludf.DUMMYFUNCTION("""COMPUTED_VALUE"""),"Code Safety/Security") -> Code Safety/Security | E40: =IFERROR(__xludf.DUMMYFUNCTION("""COMPUTED_VALUE"""),"- The code implementation has no security or safety issues") -> - The code implementation has no security or safety issues | F40: FALSE | G40: FALSE
B41: =IFERROR(__xludf.DUMMYFUNCTION("""COMPUTED_VALUE"""),"SFT") -> SFT | C41: =IFERROR(__xludf.DUMMYFUNCTION("""COMPUTED_VALUE"""),"Response") -> Response | D41: =IFERROR(__xludf.DUMMYFUNCTION("""COMPUTED_VALUE"""),"Rewrite Requirements") -> Rewrite Requirements | E41: =IFERROR(__xludf.DUMMYFUNCTION("""COMPUTED_VALUE"""),"Re-write results in a perfect response that fulfills the objectives of the prompt and has perfect code compilation and correct output. - The re-written response should fully achieve the most recent prompt. - The re-written response should address any sec"&"ondary objectives implied by the prompt. - The re-written response should correct all errors (major or minor) - The re-written response should be coherent and logically connected to the prior conversation. - The re-written response should fulfill all the "&"dimensions for ""No Issues"" in the rating rubrics. (for rubrics problems) - The re-written response should follow the formatting specifications. - The code of the re-written response should contain enough comments. (when applicable) - The code of the re-"&"written response MUST run properly and be optimal and efficient. (when applicable)") -> Re-write results in a perfect response that fulfills the objectives of the prompt and has perfect code compilation and correct output. - The re-written response should fully achieve the most recent prompt. - The re-written response should address any secondary objectives implied by the prompt. - The re-written response should correct all errors (major or minor) - The re-written response should be coherent and logically connected to the prior conversation. - The re-written response should fulfill all the dimensions for "No Issues" in the rating rubrics. (for rubrics problems) - The re-written response should follow the formatting specifications. - The code of the re-written response should contain enough comments. (when applicable) - The code of the re-written response MUST run properly and be optimal and efficient. (when applicable) | F41: FALSE | G41: FALSE
...

Sheet 2. Dimension Definition
A1: Dimension Definition | E1: Link to Net New-- Custom Dimensions | F1: Something looking wrong? Link to Debugging / Common Errors
A2: Project Team Input
A4: Selected Standard Dimensions | D4: #'s | E4: input any needed context | F4: Expand to revise >> | G4: Please write as a standard to grade to, not as a note of applicability | H4: Expand to revise >> | J4: Expand to revise >>
A5: Task Type | B5: Dimension | C5: Sub-Dimension | D5: Order of Appearance in Rubric | E5: Additional Notes for Auditors | F5: 1- 2 (Standard) | G5: 1 - 2 (Revision) | H5: 3 - 4 (Standard) | I5: 3 - 4 (Revision) | J5: 5 (Standard) | K5: 5 (Revision) | L5: Revised & Needs Review
A6: =IFERROR(__xludf.DUMMYFUNCTION("IFERROR(QUERY('1. Task Type & Dimension Select'!B9:G1032, ""SELECT Col1, Col2, Col3 WHERE (Col5 = TRUE OR Col6 = TRUE) AND Col1 IS NOT NULL ORDER BY Col5 DESC, Col6 DESC"", 0), ""(no task type and/or dimensions selected in the previous step)"") "),"All") -> All | B6: =IFERROR(__xludf.DUMMYFUNCTION("""COMPUTED_VALUE"""),"Prompt") -> Prompt | C6: =IFERROR(__xludf.DUMMYFUNCTION("""COMPUTED_VALUE"""),"Unique Ground Truth") -> Unique Ground Truth | D6: 1 | F6: {=iferror(index('A. Standard Dimensions & Rating'!E:E,match(1,('A. Standard Dimensions & Rating'!$B:$B=$A6)*('A. Standard Dimensions & Rating'!$C:$C=$B6)*('A. Standard Dimensions & Rating'!$D:$D=$C6),0)),"")} -> Fail - Multiple Valid Answers] - The prompt can reasonably produce two or more different correct answers, and the prompt does not clearly indicate which answer is intended. | H6: [Non-Fail - Multiple Valid Answers] The prompt is ambiguous, but there is either: a leading interpretation that the majority of people would pick if polled, or there are two different valid interpretations where making a small, logically defensible assumption would clarify which was intended by the user. | J6: {=iferror(index('A. Standard Dimensions & Rating'!G:G,match(1,('A. Standard Dimensions & Rating'!$B:$B=$A6)*('A. Standard Dimensions & Rating'!$C:$C=$B6)*('A. Standard Dimensions & Rating'!$D:$D=$C6),0)),"")} -> - The prompt has a unique ground truth answer. All the experts on the subject would come to the same conclusion | L6: =if(len(A6)>0,if(len(CONCATENATE(G6,I6,K6))>0,true,false),"") -> FALSE
A7: =IFERROR(__xludf.DUMMYFUNCTION("""COMPUTED_VALUE"""),"SFT") -> SFT | B7: =IFERROR(__xludf.DUMMYFUNCTION("""COMPUTED_VALUE"""),"Prompt") -> Prompt | C7: =IFERROR(__xludf.DUMMYFUNCTION("""COMPUTED_VALUE"""),"Prompt Clarity and Specificity") -> Prompt Clarity and Specificity | D7: 1 | F7: {=iferror(index('A. Standard Dimensions & Rating'!E:E,match(1,('A. Standard Dimensions & Rating'!$B:$B=$A7)*('A. Standard Dimensions & Rating'!$C:$C=$B7)*('A. Standard Dimensions & Rating'!$D:$D=$C7),0)),"")} -> [Fail - Major Clarity / Specificity Issues] - It's not clear what is being asked, the prompt is extremely difficult to follow, or is overly vague; the user intent cannot be reasonably understood from the prompt. - Major details are missing that are needed to answer the prompt and cannot be reasonably assumed | H7: {=iferror(index('A. Standard Dimensions & Rating'!F:F,match(1,('A. Standard Dimensions & Rating'!$B:$B=$A7)*('A. Standard Dimensions & Rating'!$C:$C=$B7)*('A. Standard Dimensions & Rating'!$D:$D=$C7),0)),"")} -> [Non-Fail Minor Clarity / Specificity Issues] - It's mostly clear what is being asked but the request could reasonably be interpreted multiple ways | J7: {=iferror(index('A. Standard Dimensions & Rating'!G:G,match(1,('A. Standard Dimensions & Rating'!$B:$B=$A7)*('A. Standard Dimensions & Rating'!$C:$C=$B7)*('A. Standard Dimensions & Rating'!$D:$D=$C7),0)),"")} -> - There is little to no room for misinterpretation of the specific request - Prompt has a specific request that doesn't require more than one minor assumption to answer it | L7: =if(len(A7)>0,if(len(CONCATENATE(G7,I7,K7))>0,true,false),"") -> FALSE
A8: =IFERROR(__xludf.DUMMYFUNCTION("""COMPUTED_VALUE"""),"SFT") -> SFT | B8: =IFERROR(__xludf.DUMMYFUNCTION("""COMPUTED_VALUE"""),"Prompt") -> Prompt | C8: =IFERROR(__xludf.DUMMYFUNCTION("""COMPUTED_VALUE"""),"Contrived / Unnatural Prompts") -> Contrived / Unnatural Prompts | D8: 1 | E8: This should check for artificial difficulty vs. natural complexity. Contrived examples include: demanding exact timestamps ("Find the email from January 15th at 3:47 PM"), requiring arbitrary format constraints ("Respond in exactly 3 sentences using passive voice"), or asking the agent to do something no real employee would do ("Intentionally send an incorrect email to test error handling"). Natural difficulty comes from entity confusion, scattered information, conflicting data across services, and hidden root causes. Prompts written as step-by-step command lists ("First search emails, then check CRM…") should also be considered contrived. | F8: {=iferror(index('A. Standard Dimensions & Rating'!E:E,match(1,('A. Standard Dimensions & Rating'!$B:$B=$A8)*('A. Standard Dimensions & Rating'!$C:$C=$B8)*('A. Standard Dimensions & Rating'!$D:$D=$C8),0)),"")} -> [Fail - Contrived / Unnatural Prompt] - Prompt is contrived or otherwise unnatural note: prompts such as riddles that are intentionally constraints/details laden should not be considered contrived. | H8: {=iferror(index('A. Standard Dimensions & Rating'!F:F,match(1,('A. Standard Dimensions & Rating'!$B:$B=$A8)*('A. Standard Dimensions & Rating'!$C:$C=$B8)*('A. Standard Dimensions & Rating'!$D:$D=$C8),0)),"")} -> [Non-Fail - Somewhat Contrived / Unnatural Prompt] - Prompt is somewhat contrived or is somewhat unnatural note: prompts such as riddles that are intentionally constraints/details laden should not be considered contrived. | J8: {=iferror(index('A. Standard Dimensions & Rating'!G:G,match(1,('A. Standard Dimensions & Rating'!$B:$B=$A8)*('A. Standard Dimensions & Rating'!$C:$C=$B8)*('A. Standard Dimensions & Rating'!$D:$D=$C8),0)),"")} -> - The prompt is neither contrived or unnatural | L8: =if(len(A8)>0,if(len(CONCATENATE(G8,I8,K8))>0,true,false),"") -> FALSE
A9: =IFERROR(__xludf.DUMMYFUNCTION("""COMPUTED_VALUE"""),"SFT") -> SFT | B9: =IFERROR(__xludf.DUMMYFUNCTION("""COMPUTED_VALUE"""),"Prompt") -> Prompt | C9: =IFERROR(__xludf.DUMMYFUNCTION("""COMPUTED_VALUE"""),"Truthfulness") -> Truthfulness | D9: 1 | F9: {=iferror(index('A. Standard Dimensions & Rating'!E:E,match(1,('A. Standard Dimensions & Rating'!$B:$B=$A9)*('A. Standard Dimensions & Rating'!$C:$C=$B9)*('A. Standard Dimensions & Rating'!$D:$D=$C9),0)),"")} -> [Fail - Major Factual Errors] - The prompt contains 1 or more major factual errors [Fail - Minor Factual Errors] - The prompt contains 2 or more minor factual errors (e.g., statements irrelevant to the fulfillment of the prompt's request) | H9: {=iferror(index('A. Standard Dimensions & Rating'!F:F,match(1,('A. Standard Dimensions & Rating'!$B:$B=$A9)*('A. Standard Dimensions & Rating'!$C:$C=$B9)*('A. Standard Dimensions & Rating'!$D:$D=$C9),0)),"")} -> [Non-Fail - Minor Factual Errors] - The prompt contains 1 minor factual errors. | J9: {=iferror(index('A. Standard Dimensions & Rating'!G:G,match(1,('A. Standard Dimensions & Rating'!$B:$B=$A9)*('A. Standard Dimensions & Rating'!$C:$C=$B9)*('A. Standard Dimensions & Rating'!$D:$D=$C9),0)),"")} -> - The prompt has no factual errors - The prompt has no misleading statements | L9: =if(len(A9)>0,if(len(CONCATENATE(G9,I9,K9))>0,true,false),"") -> FALSE
D10: 1 | F10: {=iferror(index('A. Standard Dimensions & Rating'!E:E,match(1,('A. Standard Dimensions & Rating'!$B:$B=$A10)*('A. Standard Dimensions & Rating'!$C:$C=$B10)*('A. Standard Dimensions & Rating'!$D:$D=$C10),0)),"")} | H10: {=iferror(index('A. Standard Dimensions & Rating'!F:F,match(1,('A. Standard Dimensions & Rating'!$B:$B=$A10)*('A. Standard Dimensions & Rating'!$C:$C=$B10)*('A. Standard Dimensions & Rating'!$D:$D=$C10),0)),"")} | J10: {=iferror(index('A. Standard Dimensions & Rating'!G:G,match(1,('A. Standard Dimensions & Rating'!$B:$B=$A10)*('A. Standard Dimensions & Rating'!$C:$C=$B10)*('A. Standard Dimensions & Rating'!$D:$D=$C10),0)),"")} | L10: =if(len(A10)>0,if(len(CONCATENATE(G10,I10,K10))>0,true,false),"")
D11: 1 | F11: {=iferror(index('A. Standard Dimensions & Rating'!E:E,match(1,('A. Standard Dimensions & Rating'!$B:$B=$A11)*('A. Standard Dimensions & Rating'!$C:$C=$B11)*('A. Standard Dimensions & Rating'!$D:$D=$C11),0)),"")} | H11: {=iferror(index('A. Standard Dimensions & Rating'!F:F,match(1,('A. Standard Dimensions & Rating'!$B:$B=$A11)*('A. Standard Dimensions & Rating'!$C:$C=$B11)*('A. Standard Dimensions & Rating'!$D:$D=$C11),0)),"")} | J11: {=iferror(index('A. Standard Dimensions & Rating'!G:G,match(1,('A. Standard Dimensions & Rating'!$B:$B=$A11)*('A. Standard Dimensions & Rating'!$C:$C=$B11)*('A. Standard Dimensions & Rating'!$D:$D=$C11),0)),"")} | L11: =if(len(A11)>0,if(len(CONCATENATE(G11,I11,K11))>0,true,false),"")
D12: 2 | F12: {=iferror(index('A. Standard Dimensions & Rating'!E:E,match(1,('A. Standard Dimensions & Rating'!$B:$B=$A12)*('A. Standard Dimensions & Rating'!$C:$C=$B12)*('A. Standard Dimensions & Rating'!$D:$D=$C12),0)),"")} | H12: {=iferror(index('A. Standard Dimensions & Rating'!F:F,match(1,('A. Standard Dimensions & Rating'!$B:$B=$A12)*('A. Standard Dimensions & Rating'!$C:$C=$B12)*('A. Standard Dimensions & Rating'!$D:$D=$C12),0)),"")} | J12: {=iferror(index('A. Standard Dimensions & Rating'!G:G,match(1,('A. Standard Dimensions & Rating'!$B:$B=$A12)*('A. Standard Dimensions & Rating'!$C:$C=$B12)*('A. Standard Dimensions & Rating'!$D:$D=$C12),0)),"")} | L12: =if(len(A12)>0,if(len(CONCATENATE(G12,I12,K12))>0,true,false),"")
D13: 2 | F13: {=iferror(index('A. Standard Dimensions & Rating'!E:E,match(1,('A. Standard Dimensions & Rating'!$B:$B=$A13)*('A. Standard Dimensions & Rating'!$C:$C=$B13)*('A. Standard Dimensions & Rating'!$D:$D=$C13),0)),"")} | H13: {=iferror(index('A. Standard Dimensions & Rating'!F:F,match(1,('A. Standard Dimensions & Rating'!$B:$B=$A13)*('A. Standard Dimensions & Rating'!$C:$C=$B13)*('A. Standard Dimensions & Rating'!$D:$D=$C13),0)),"")} | J13: {=iferror(index('A. Standard Dimensions & Rating'!G:G,match(1,('A. Standard Dimensions & Rating'!$B:$B=$A13)*('A. Standard Dimensions & Rating'!$C:$C=$B13)*('A. Standard Dimensions & Rating'!$D:$D=$C13),0)),"")} | L13: =if(len(A13)>0,if(len(CONCATENATE(G13,I13,K13))>0,true,false),"")
D14: 2 | F14: {=iferror(index('A. Standard Dimensions & Rating'!E:E,match(1,('A. Standard Dimensions & Rating'!$B:$B=$A14)*('A. Standard Dimensions & Rating'!$C:$C=$B14)*('A. Standard Dimensions & Rating'!$D:$D=$C14),0)),"")} | H14: {=iferror(index('A. Standard Dimensions & Rating'!F:F,match(1,('A. Standard Dimensions & Rating'!$B:$B=$A14)*('A. Standard Dimensions & Rating'!$C:$C=$B14)*('A. Standard Dimensions & Rating'!$D:$D=$C14),0)),"")} | J14: {=iferror(index('A. Standard Dimensions & Rating'!G:G,match(1,('A. Standard Dimensions & Rating'!$B:$B=$A14)*('A. Standard Dimensions & Rating'!$C:$C=$B14)*('A. Standard Dimensions & Rating'!$D:$D=$C14),0)),"")} | L14: =if(len(A14)>0,if(len(CONCATENATE(G14,I14,K14))>0,true,false),"")
D15: 3 | F15: {=iferror(index('A. Standard Dimensions & Rating'!E:E,match(1,('A. Standard Dimensions & Rating'!$B:$B=$A15)*('A. Standard Dimensions & Rating'!$C:$C=$B15)*('A. Standard Dimensions & Rating'!$D:$D=$C15),0)),"")} | H15: {=iferror(index('A. Standard Dimensions & Rating'!F:F,match(1,('A. Standard Dimensions & Rating'!$B:$B=$A15)*('A. Standard Dimensions & Rating'!$C:$C=$B15)*('A. Standard Dimensions & Rating'!$D:$D=$C15),0)),"")} | J15: {=iferror(index('A. Standard Dimensions & Rating'!G:G,match(1,('A. Standard Dimensions & Rating'!$B:$B=$A15)*('A. Standard Dimensions & Rating'!$C:$C=$B15)*('A. Standard Dimensions & Rating'!$D:$D=$C15),0)),"")} | L15: =if(len(A15)>0,if(len(CONCATENATE(G15,I15,K15))>0,true,false),"")
D16: 3 | F16: {=iferror(index('A. Standard Dimensions & Rating'!E:E,match(1,('A. Standard Dimensions & Rating'!$B:$B=$A16)*('A. Standard Dimensions & Rating'!$C:$C=$B16)*('A. Standard Dimensions & Rating'!$D:$D=$C16),0)),"")} | H16: {=iferror(index('A. Standard Dimensions & Rating'!F:F,match(1,('A. Standard Dimensions & Rating'!$B:$B=$A16)*('A. Standard Dimensions & Rating'!$C:$C=$B16)*('A. Standard Dimensions & Rating'!$D:$D=$C16),0)),"")} | J16: {=iferror(index('A. Standard Dimensions & Rating'!G:G,match(1,('A. Standard Dimensions & Rating'!$B:$B=$A16)*('A. Standard Dimensions & Rating'!$C:$C=$B16)*('A. Standard Dimensions & Rating'!$D:$D=$C16),0)),"")} | L16: =if(len(A16)>0,if(len(CONCATENATE(G16,I16,K16))>0,true,false),"")
D17: 3 | F17: {=iferror(index('A. Standard Dimensions & Rating'!E:E,match(1,('A. Standard Dimensions & Rating'!$B:$B=$A17)*('A. Standard Dimensions & Rating'!$C:$C=$B17)*('A. Standard Dimensions & Rating'!$D:$D=$C17),0)),"")} | H17: {=iferror(index('A. Standard Dimensions & Rating'!F:F,match(1,('A. Standard Dimensions & Rating'!$B:$B=$A17)*('A. Standard Dimensions & Rating'!$C:$C=$B17)*('A. Standard Dimensions & Rating'!$D:$D=$C17),0)),"")} | J17: {=iferror(index('A. Standard Dimensions & Rating'!G:G,match(1,('A. Standard Dimensions & Rating'!$B:$B=$A17)*('A. Standard Dimensions & Rating'!$C:$C=$B17)*('A. Standard Dimensions & Rating'!$D:$D=$C17),0)),"")} | L17: =if(len(A17)>0,if(len(CONCATENATE(G17,I17,K17))>0,true,false),"")
F18: {=iferror(index('A. Standard Dimensions & Rating'!E:E,match(1,('A. Standard Dimensions & Rating'!$B:$B=$A18)*('A. Standard Dimensions & Rating'!$C:$C=$B18)*('A. Standard Dimensions & Rating'!$D:$D=$C18),0)),"")} | H18: {=iferror(index('A. Standard Dimensions & Rating'!F:F,match(1,('A. Standard Dimensions & Rating'!$B:$B=$A18)*('A. Standard Dimensions & Rating'!$C:$C=$B18)*('A. Standard Dimensions & Rating'!$D:$D=$C18),0)),"")} | J18: {=iferror(index('A. Standard Dimensions & Rating'!G:G,match(1,('A. Standard Dimensions & Rating'!$B:$B=$A18)*('A. Standard Dimensions & Rating'!$C:$C=$B18)*('A. Standard Dimensions & Rating'!$D:$D=$C18),0)),"")} | L18: =if(len(A18)>0,if(len(CONCATENATE(G18,I18,K18))>0,true,false),"")
F19: {=iferror(index('A. Standard Dimensions & Rating'!E:E,match(1,('A. Standard Dimensions & Rating'!$B:$B=$A19)*('A. Standard Dimensions & Rating'!$C:$C=$B19)*('A. Standard Dimensions & Rating'!$D:$D=$C19),0)),"")} | H19: {=iferror(index('A. Standard Dimensions & Rating'!F:F,match(1,('A. Standard Dimensions & Rating'!$B:$B=$A19)*('A. Standard Dimensions & Rating'!$C:$C=$B19)*('A. Standard Dimensions & Rating'!$D:$D=$C19),0)),"")} | J19: {=iferror(index('A. Standard Dimensions & Rating'!G:G,match(1,('A. Standard Dimensions & Rating'!$B:$B=$A19)*('A. Standard Dimensions & Rating'!$C:$C=$B19)*('A. Standard Dimensions & Rating'!$D:$D=$C19),0)),"")} | L19: =if(len(A19)>0,if(len(CONCATENATE(G19,I19,K19))>0,true,false),"")
F20: {=iferror(index('A. Standard Dimensions & Rating'!E:E,match(1,('A. Standard Dimensions & Rating'!$B:$B=$A20)*('A. Standard Dimensions & Rating'!$C:$C=$B20)*('A. Standard Dimensions & Rating'!$D:$D=$C20),0)),"")} | H20: {=iferror(index('A. Standard Dimensions & Rating'!F:F,match(1,('A. Standard Dimensions & Rating'!$B:$B=$A20)*('A. Standard Dimensions & Rating'!$C:$C=$B20)*('A. Standard Dimensions & Rating'!$D:$D=$C20),0)),"")} | J20: {=iferror(index('A. Standard Dimensions & Rating'!G:G,match(1,('A. Standard Dimensions & Rating'!$B:$B=$A20)*('A. Standard Dimensions & Rating'!$C:$C=$B20)*('A. Standard Dimensions & Rating'!$D:$D=$C20),0)),"")} | L20: =if(len(A20)>0,if(len(CONCATENATE(G20,I20,K20))>0,true,false),"")
F21: {=iferror(index('A. Standard Dimensions & Rating'!E:E,match(1,('A. Standard Dimensions & Rating'!$B:$B=$A21)*('A. Standard Dimensions & Rating'!$C:$C=$B21)*('A. Standard Dimensions & Rating'!$D:$D=$C21),0)),"")} | H21: {=iferror(index('A. Standard Dimensions & Rating'!F:F,match(1,('A. Standard Dimensions & Rating'!$B:$B=$A21)*('A. Standard Dimensions & Rating'!$C:$C=$B21)*('A. Standard Dimensions & Rating'!$D:$D=$C21),0)),"")} | J21: {=iferror(index('A. Standard Dimensions & Rating'!G:G,match(1,('A. Standard Dimensions & Rating'!$B:$B=$A21)*('A. Standard Dimensions & Rating'!$C:$C=$B21)*('A. Standard Dimensions & Rating'!$D:$D=$C21),0)),"")} | L21: =if(len(A21)>0,if(len(CONCATENATE(G21,I21,K21))>0,true,false),"")
F22: {=iferror(index('A. Standard Dimensions & Rating'!E:E,match(1,('A. Standard Dimensions & Rating'!$B:$B=$A22)*('A. Standard Dimensions & Rating'!$C:$C=$B22)*('A. Standard Dimensions & Rating'!$D:$D=$C22),0)),"")} | H22: {=iferror(index('A. Standard Dimensions & Rating'!F:F,match(1,('A. Standard Dimensions & Rating'!$B:$B=$A22)*('A. Standard Dimensions & Rating'!$C:$C=$B22)*('A. Standard Dimensions & Rating'!$D:$D=$C22),0)),"")} | J22: {=iferror(index('A. Standard Dimensions & Rating'!G:G,match(1,('A. Standard Dimensions & Rating'!$B:$B=$A22)*('A. Standard Dimensions & Rating'!$C:$C=$B22)*('A. Standard Dimensions & Rating'!$D:$D=$C22),0)),"")} | L22: =if(len(A22)>0,if(len(CONCATENATE(G22,I22,K22))>0,true,false),"")
F23: {=iferror(index('A. Standard Dimensions & Rating'!E:E,match(1,('A. Standard Dimensions & Rating'!$B:$B=$A23)*('A. Standard Dimensions & Rating'!$C:$C=$B23)*('A. Standard Dimensions & Rating'!$D:$D=$C23),0)),"")} | H23: {=iferror(index('A. Standard Dimensions & Rating'!F:F,match(1,('A. Standard Dimensions & Rating'!$B:$B=$A23)*('A. Standard Dimensions & Rating'!$C:$C=$B23)*('A. Standard Dimensions & Rating'!$D:$D=$C23),0)),"")} | J23: {=iferror(index('A. Standard Dimensions & Rating'!G:G,match(1,('A. Standard Dimensions & Rating'!$B:$B=$A23)*('A. Standard Dimensions & Rating'!$C:$C=$B23)*('A. Standard Dimensions & Rating'!$D:$D=$C23),0)),"")} | L23: =if(len(A23)>0,if(len(CONCATENATE(G23,I23,K23))>0,true,false),"")
F24: {=iferror(index('A. Standard Dimensions & Rating'!E:E,match(1,('A. Standard Dimensions & Rating'!$B:$B=$A24)*('A. Standard Dimensions & Rating'!$C:$C=$B24)*('A. Standard Dimensions & Rating'!$D:$D=$C24),0)),"")} | H24: {=iferror(index('A. Standard Dimensions & Rating'!F:F,match(1,('A. Standard Dimensions & Rating'!$B:$B=$A24)*('A. Standard Dimensions & Rating'!$C:$C=$B24)*('A. Standard Dimensions & Rating'!$D:$D=$C24),0)),"")} | J24: {=iferror(index('A. Standard Dimensions & Rating'!G:G,match(1,('A. Standard Dimensions & Rating'!$B:$B=$A24)*('A. Standard Dimensions & Rating'!$C:$C=$B24)*('A. Standard Dimensions & Rating'!$D:$D=$C24),0)),"")} | L24: =if(len(A24)>0,if(len(CONCATENATE(G24,I24,K24))>0,true,false),"")
F25: {=iferror(index('A. Standard Dimensions & Rating'!E:E,match(1,('A. Standard Dimensions & Rating'!$B:$B=$A25)*('A. Standard Dimensions & Rating'!$C:$C=$B25)*('A. Standard Dimensions & Rating'!$D:$D=$C25),0)),"")} | H25: {=iferror(index('A. Standard Dimensions & Rating'!F:F,match(1,('A. Standard Dimensions & Rating'!$B:$B=$A25)*('A. Standard Dimensions & Rating'!$C:$C=$B25)*('A. Standard Dimensions & Rating'!$D:$D=$C25),0)),"")} | J25: {=iferror(index('A. Standard Dimensions & Rating'!G:G,match(1,('A. Standard Dimensions & Rating'!$B:$B=$A25)*('A. Standard Dimensions & Rating'!$C:$C=$B25)*('A. Standard Dimensions & Rating'!$D:$D=$C25),0)),"")} | L25: =if(len(A25)>0,if(len(CONCATENATE(G25,I25,K25))>0,true,false),"")
F26: {=iferror(index('A. Standard Dimensions & Rating'!E:E,match(1,('A. Standard Dimensions & Rating'!$B:$B=$A26)*('A. Standard Dimensions & Rating'!$C:$C=$B26)*('A. Standard Dimensions & Rating'!$D:$D=$C26),0)),"")} | H26: {=iferror(index('A. Standard Dimensions & Rating'!F:F,match(1,('A. Standard Dimensions & Rating'!$B:$B=$A26)*('A. Standard Dimensions & Rating'!$C:$C=$B26)*('A. Standard Dimensions & Rating'!$D:$D=$C26),0)),"")} | J26: {=iferror(index('A. Standard Dimensions & Rating'!G:G,match(1,('A. Standard Dimensions & Rating'!$B:$B=$A26)*('A. Standard Dimensions & Rating'!$C:$C=$B26)*('A. Standard Dimensions & Rating'!$D:$D=$C26),0)),"")} | L26: =if(len(A26)>0,if(len(CONCATENATE(G26,I26,K26))>0,true,false),"")
F27: {=iferror(index('A. Standard Dimensions & Rating'!E:E,match(1,('A. Standard Dimensions & Rating'!$B:$B=$A27)*('A. Standard Dimensions & Rating'!$C:$C=$B27)*('A. Standard Dimensions & Rating'!$D:$D=$C27),0)),"")} | H27: {=iferror(index('A. Standard Dimensions & Rating'!F:F,match(1,('A. Standard Dimensions & Rating'!$B:$B=$A27)*('A. Standard Dimensions & Rating'!$C:$C=$B27)*('A. Standard Dimensions & Rating'!$D:$D=$C27),0)),"")} | J27: {=iferror(index('A. Standard Dimensions & Rating'!G:G,match(1,('A. Standard Dimensions & Rating'!$B:$B=$A27)*('A. Standard Dimensions & Rating'!$C:$C=$B27)*('A. Standard Dimensions & Rating'!$D:$D=$C27),0)),"")} | L27: =if(len(A27)>0,if(len(CONCATENATE(G27,I27,K27))>0,true,false),"")
F28: {=iferror(index('A. Standard Dimensions & Rating'!E:E,match(1,('A. Standard Dimensions & Rating'!$B:$B=$A28)*('A. Standard Dimensions & Rating'!$C:$C=$B28)*('A. Standard Dimensions & Rating'!$D:$D=$C28),0)),"")} | H28: {=iferror(index('A. Standard Dimensions & Rating'!F:F,match(1,('A. Standard Dimensions & Rating'!$B:$B=$A28)*('A. Standard Dimensions & Rating'!$C:$C=$B28)*('A. Standard Dimensions & Rating'!$D:$D=$C28),0)),"")} | J28: {=iferror(index('A. Standard Dimensions & Rating'!G:G,match(1,('A. Standard Dimensions & Rating'!$B:$B=$A28)*('A. Standard Dimensions & Rating'!$C:$C=$B28)*('A. Standard Dimensions & Rating'!$D:$D=$C28),0)),"")} | L28: =if(len(A28)>0,if(len(CONCATENATE(G28,I28,K28))>0,true,false),"")
F29: {=iferror(index('A. Standard Dimensions & Rating'!E:E,match(1,('A. Standard Dimensions & Rating'!$B:$B=$A29)*('A. Standard Dimensions & Rating'!$C:$C=$B29)*('A. Standard Dimensions & Rating'!$D:$D=$C29),0)),"")} | H29: {=iferror(index('A. Standard Dimensions & Rating'!F:F,match(1,('A. Standard Dimensions & Rating'!$B:$B=$A29)*('A. Standard Dimensions & Rating'!$C:$C=$B29)*('A. Standard Dimensions & Rating'!$D:$D=$C29),0)),"")} | J29: {=iferror(index('A. Standard Dimensions & Rating'!G:G,match(1,('A. Standard Dimensions & Rating'!$B:$B=$A29)*('A. Standard Dimensions & Rating'!$C:$C=$B29)*('A. Standard Dimensions & Rating'!$D:$D=$C29),0)),"")} | L29: =if(len(A29)>0,if(len(CONCATENATE(G29,I29,K29))>0,true,false),"")
... F49: {=iferror(index('A. Standard Dimensions & Rating'!E:E,match(1,('A. Standard Dimensions & Rating'!$B:$B=$A49)*('A. Standard Dimensions & Rating'!$C:$C=$B49)*('A. Standard Dimensions & Rating'!$D:$D=$C49),0)),"")} | H49: {=iferror(index('A. Standard Dimensions & Rating'!F:F,match(1,('A. Standard Dimensions & Rating'!$B:$B=$A49)*('A. Standard Dimensions & Rating'!$C:$C=$B49)*('A. Standard Dimensions & Rating'!$D:$D=$C49),0)),"")} | J49: {=iferror(index('A. Standard Dimensions & Rating'!G:G,match(1,('A. Standard Dimensions & Rating'!$B:$B=$A49)*('A. Standard Dimensions & Rating'!$C:$C=$B49)*('A. Standard Dimensions & Rating'!$D:$D=$C49),0)),"")} | L49: =if(len(A49)>0,if(len(CONCATENATE(G49,I49,K49))>0,true,false),"")
F50: {=iferror(index('Original Copy of Standard Dimen'!E:E,match(1,('Original Copy of Standard Dimen'!$A:$A=$A50)*('Original Copy of Standard Dimen'!$B:$B=$B50)*('Original Copy of Standard Dimen'!$C:$C=$C50),0)),"")} | H50: {=iferror(index('Original Copy of Standard Dimen'!F:F,match(1,('Original Copy of Standard Dimen'!$A:$A=$A50)*('Original Copy of Standard Dimen'!$B:$B=$B50)*('Original Copy of Standard Dimen'!$C:$C=$C50),0)),"")} | J50: {=iferror(index('Original Copy of Standard Dimen'!G:G,match(1,('Original Copy of Standard Dimen'!$A:$A=$A50)*('Original Copy of Standard Dimen'!$B:$B=$B50)*('Original Copy of Standard Dimen'!$C:$C=$C50),0)),"")} | L50: =if(len(A50)>0,if(len(CONCATENATE(G50,I50,K50))>0,true,false),"")
A51: Additional Custom Dimensions
A52: Task Type | B52: Dimension | C52: Sub-Dimension | E52: Additional Notes for Auditors | F52: 1 (Custom) | H52: 3 (Custom) | J52: 5 (Custom) | L52: Complete
A53: RL | B53: Prompt | C53: Feasibility | D53: 1 | F53: [Fail - Prompt Impractical Request] - Prompt contains an impractical request that can't be answered by an LLM in a single response [Fail - Prompt Impossible Request] - Prompt has at least one request that can't be fulfilled at all [Fail - Prompt Conflicting Instructions] - Prompt gives instructions that conflict/contradict with itself that can't be fulfilled simultaneously [Fail - Prompt Feasibility with Tools] - Prompt contains an impractical or impossible request that can't be answered by the tools available or enabled for the task | H53: Non-Fail - Prompt Impractical Secondary Request] - There are multiple requests in the prompt and it's verging on being impractical for a model to answer it in a single response, but the core request of the prompt can be fulfilled with minor concessions on the secondary requests | J53: - The prompt is completely actionable by an LLM agent. - The prompt contains no conflicting instructions/statements | L53: =if(and(len(A53)>0,len(B53)>0,len(C53)>0,len(F53)>0),true,) -> TRUE
A54: RL | B54: Prompt | C54: Tool use and Cross-service requirement | D54: 2 | F54: [Fail - Tool Dependence] - The prompt can be answered without having to make any tool calls (either through basic reasoning or general knowledge) [Fail - Cross-service Requirement] - Prompt can be fully resolved within a single service (e.g., just email or just CRM), or only trivially touches a second service. | H54: N/A | J54: - Prompt requires investigation across 2+ services to answer correctly (e.g., facts needed are scattered and must be reconciled). | L54: =if(and(len(A54)>0,len(B54)>0,len(C54)>0,len(F54)>0),true,) -> TRUE
A55: RL | B55: Prompt | C55: Explicit Tool Mention | D55: 1 | F55: [Fail - Explicit Tool Mention] The prompt explicitly mentions a specific tool name The prompt unnaturally refers to an MCP server in an inorganic, technical manner “Use the Airbnb tool to…” (technical, unnatural) “I want to use Airbnb to find…” (general, natural) | H55: N/A | J55: - The prompt does not explicitly state the use of tools | L55: =if(and(len(A55)>0,len(B55)>0,len(C55)>0,len(F55)>0),true,) -> TRUE
A56: RL | B56: Prompt | C56: Investigation + Action | D56: 2 | F56: [Fail - Action Missing] - Prompt only asks for a summary/report/research with no required action. [Fail - Pre-solved] - Prompt tells agent the root cause and no investigation is needed. | H56: N/A | J56: Prompt clearly requires investigtion and at least one concrete action (email, ticket creation/update, booking, calendar scheduling, CRM update, etc.), and it logically follows from investigation. | L56: =if(and(len(A56)>0,len(B56)>0,len(C56)>0,len(F56)>0),true,) -> TRUE
A57: RL | B57: Prompt | C57: Coherence | D57: 2 | E57: An example of failing bolt-on requests: "Check weather in Miami, update my calendar for next week, email Marcus about Q3, and look up Seattle flights." Why it fails: Four unrelated requests stapled together. Each sub-request should causally flow from the same situation. How to tell if your prompt is "bolted": Remove any one sentence. If the rest still makes perfect sense without it, that sentence is a bolt-on | F57: [Fail - Bolt-on requests] - Contains unrelated bolt-on requests; removing a sentence doesn’t change the rest. | H57: N/A | J57: One cohesive situation; stacked asks all tie back to the same purpose. | L57: =if(and(len(A57)>0,len(B57)>0,len(C57)>0,len(F57)>0),true,) -> TRUE
A58: RL | B58: Universe | C58: Universe Feasibility (Data Exists) | D58: 3 | E58: Auditors should check the Universe Explorer or Sandbox to verify that key data needed for the prompt exists. | F58: [Fail - Missing Universe Data] - Task depends on key facts/entities/events that do not exist in the universe (or cannot be retrieved with available tools), making the task unsolvable. | H58: N/A | J58: All core facts required to solve the task exist in the universe and are retrievable via tools. | L58: =if(and(len(A58)>0,len(B58)>0,len(C58)>0,len(F58)>0),true,) -> TRUE
A59: RL | B59: Universe | C59: Cross-service Coherence | D59: 3 | E59: Auditors should refer to the changelog table in the sandbox to check changes that were made to the universe (if edits were made). | F59: [Fail - Incoherent Universe Changes] - Universe edits create contradictions that break solvability or realism (e.g., mismatched names across email vs CRM, impossible dates, entities referenced in one service but not elsewhere when required). Note: When evaluating a contradiction, if there is sufficient supporting evidence to support one piece of information against a contradicting low-supported piece of information, do not count that as a contradiction. | J59: Universe edits (if any) are internally consistent and coherent across services, including dates, names, and storyline continuity. | L59: =if(and(len(A59)>0,len(B59)>0,len(C59)>0,len(F59)>0),true,) -> TRUE
A60: RL | B60: Oracle Events (OEs) | C60: OE Accuracy | D60: 4 | E60: Auditors should verify OEs against the universe data using the Explorer or Sandbox. Each OE should reference the correct tool, correct service, correct parameters, and correct expected data. An OE that describes "look up Fatimah's relocations in Linear" when relocation records are actually in the CRM is inaccurate — the data exists but the OE points to the wrong place. OE Accuracy is distinct from OE Completeness: completeness checks whether steps are missing; accuracy checks whether the steps that exist are correct. | F60: N/A | H60: [Non-Fail - Minor OE Inaccuracies] OEs are substantively correct but contain minor imprecisions (e.g., slightly wrong parameter name that doesn't change the outcome, approximate rather than exact expected values for freetext fields). [Non-Fail - Inaccurate Oracle Events] One or more OEs reference the wrong tool, wrong service, wrong parameters, or wrong expected data. The described steps would not produce the correct results if followed literally (e.g., searching the wrong service for data that lives elsewhere, expecting data that doesn't match the universe, specifying incorrect entity names or identifiers). | J60: All OEs are factually accurate. Tools, services, parameters, and expected data match the universe. Following the OEs literally would produce a correct trajectory. | L60: =if(and(len(A60)>0,len(B60)>0,len(C60)>0,len(F60)>0),true,) -> TRUE
...

Sheet 3. ML & QC Review
A1: ML & QC Review | C1: Status: | D1: ` | E1: Please perform any agreed edits at this stage on Tab 2 | G1: Please perform any agreed edits at this stage on Tab 2 | I1: Please perform any agreed edits at this stage on Tab 2 | K1: Please perform any agreed edits at this stage on Tab 2
A2: ML & QC Input Only | C2: =if(countifs(A6:A33,"<>",K6:K33,"<>Approved")+countifs(A6:A33,"<>",O6:O33,"<>Approved")+countifs(A36:A1013,"<>",K36:K1013,"<>Approved")+countifs(A36:A1013,"<>",O36:O1013,"<>Approved")>0,"Pending Approval","Approved") -> Approved
A4: Revised Dimensions | K4: See Full Rubric Preview | O4: See Full Rubric Preview
A5: Task Type | B5: Dimension | C5: Sub-Dimension | D5: Notes | E5: 1 - 2 (Standard) | F5: 1 - 2 (Revision) | G5: 3 - 4 (Standard) | H5: 3 - 4 (Revision) | I5: 5 (Standard) | J5: 5 (Revision) | K5: QC Approval | L5: QC AM/ Auditor Lead Designee | M5: QC Approval Date/Time | N5: QC Suggestion | O5: ML Approval | P5: ML Approver | Q5: ML Approval Date/Time | R5: ML Suggestion
A6: =IFERROR(__xludf.DUMMYFUNCTION("iferror(filter('2. Dimension Definition'!A6:C50,'2. Dimension Definition'!L6:L50=true))"),"") | D6: =IFERROR(__xludf.DUMMYFUNCTION("iferror(filter('2. Dimension Definition'!E6:K50,'2. Dimension Definition'!L6:L50=true),""(no revised dimensions)"")"),"(no revised dimensions)") -> (no revised dimensions) | K6: Pending Review / Edits | O6: Pending Review / Edits
A34: Additional Custom Dimensions | E34: Note: If an error appears in D36 please delete the contents of E36 -- J36 and down, this will allow range to be expanded. Ignore edit warnings
A35: Task Type | B35: Dimension | C35: Sub-Dimension | D35: Notes | E35: 1 (Custom) | G35: 3 (Custom) | I35: 5 (Custom) | K35: QC Approval | L35: Approval Date/Time | N35: QC Suggestion | O35: ML Approval | P35: ML Approver | Q35: ML Approval Date/Time | R35: ML Suggestion
A36: =IFERROR(__xludf.DUMMYFUNCTION("iferror(filter('2. Dimension Definition'!A53:C1013,'2. Dimension Definition'!L53:L1013=true),""(no custom dimensions)"")"),"RL") -> RL | B36: =IFERROR(__xludf.DUMMYFUNCTION("""COMPUTED_VALUE"""),"Prompt") -> Prompt | C36: =IFERROR(__xludf.DUMMYFUNCTION("""COMPUTED_VALUE"""),"Feasibility") -> Feasibility | D36: =IFERROR(__xludf.DUMMYFUNCTION("iferror(filter('2. Dimension Definition'!E53:J1013,'2. Dimension Definition'!L53:L1013=true),""(no custom dimensions)"")"),"") | E36: =IFERROR(__xludf.DUMMYFUNCTION("""COMPUTED_VALUE"""),"[Fail - Prompt Impractical Request] - Prompt contains an impractical request that can't be answered by an LLM in a single response [Fail - Prompt Impossible Request] - Prompt has at least one request that can't be fulfilled at all [Fail - Prompt Conflic"&"ting Instructions] - Prompt gives instructions that conflict/contradict with itself that can't be fulfilled simultaneously [Fail - Prompt Feasibility with Tools] - Prompt contains an impractical or impossible request that can't be answered by the tools a"&"vailable or enabled for the task") -> [Fail - Prompt Impractical Request] - Prompt contains an impractical request that can't be answered by an LLM in a single response [Fail - Prompt Impossible Request] - Prompt has at least one request that can't be fulfilled at all [Fail - Prompt Conflicting Instructions] - Prompt gives instructions that conflict/contradict with itself that can't be fulfilled simultaneously [Fail - Prompt Feasibility with Tools] - Prompt contains an impractical or impossible request that can't be answered by the tools available or enabled for the task | G36: =IFERROR(__xludf.DUMMYFUNCTION("""COMPUTED_VALUE"""),"Non-Fail - Prompt Impractical Secondary Request] - There are multiple requests in the prompt and it's verging on being impractical for a model to answer it in a single response, but the core request of the prompt can be fulfilled with minor concessions on"&" the secondary requests") -> Non-Fail - Prompt Impractical Secondary Request] - There are multiple requests in the prompt and it's verging on being impractical for a model to answer it in a single response, but the core request of the prompt can be fulfilled with minor concessions on the secondary requests | I36: =IFERROR(__xludf.DUMMYFUNCTION("""COMPUTED_VALUE"""),"- The prompt is completely actionable by an LLM agent. - The prompt contains no conflicting instructions/statements") -> - The prompt is completely actionable by an LLM agent. - The prompt contains no conflicting instructions/statements | K36: Approved | L36: Varun Kumar Velidandi | M36: 3 PM PST, Mar 5 2026 | O36: Approved | R36: Reviewed by ML in alignment call
